Workbook

Sheet Database
A1: Giornata | B1: Squadra | C1: Modulo | D1: Giocatore | E1: Ruolo | F1: Voto | G1: Fantavoto | H1: BonusMalus | I1: Titolare | J1: VotoUtile | K1: Sostituisce | L1: VdM (mln €)
A2: 1 | B2: Incontro al capitano | C2: 3-5-2 | D2: Maignan | E2: P | F2: 6 | G2: 5 | H2: -1 | I2: SI | J2: SI | L2: 20
A3: 1 | B3: Incontro al capitano | C3: 3-5-2 | D3: Bremer | E3: D | F3: 7 | G3: 10 | H3: 3 | I3: SI | J3: SI | L3: 35
A4: 1 | B4: Incontro al capitano | C4: 3-5-2 | D4: Stones | E4: D | F4: 6 | G4: 6 | H4: 0 | I4: SI | J4: SI | L4: 12
A5: 1 | B5: Incontro al capitano | C5: 3-5-2 | D5: Molina N. | E5: D | I5: SI | J5: NO | L5: 15
A6: 1 | B6: Incontro al capitano | C6: 3-5-2 | D6: Dominguez B. | E6: C | F6: 6 | G6: 6 | H6: 0 | I6: SI | J6: SI | L6: 9
A7: 1 | B7: Incontro al capitano | C7: 3-5-2 | D7: Casadei | E7: C | F7: 5 | G7: 5 | H7: 0 | I7: SI | J7: SI | L7: 15
A8: 1 | B8: Incontro al capitano | C8: 3-5-2 | D8: Modric | E8: C | F8: 6.5 | G8: 6.5 | H8: 0 | I8: SI | J8: SI | L8: 3.5
A9: 1 | B9: Incontro al capitano | C9: 3-5-2 | D9: Taylor K. | E9: C | F9: 6.5 | G9: 6.5 | H9: 0 | I9: SI | J9: SI | L9: 25
A10: 1 | B10: Incontro al capitano | C10: 3-5-2 | D10: Paz N. | E10: C | F10: 5.5 | G10: 5.5 | H10: 0 | I10: SI | J10: SI | L10: 80
A11: 1 | B11: Incontro al capitano | C11: 3-5-2 | D11: Boga | E11: A | F11: 5.5 | G11: 5.5 | H11: 0 | I11: SI | J11: SI | L11: 8
A12: 1 | B12: Incontro al capitano | C12: 3-5-2 | D12: Dybala | E12: A | F12: 8 | G12: 11 | H12: 3 | I12: SI | J12: SI | L12: 5
A13: 1 | B13: Incontro al capitano | C13: 3-5-2 | D13: Terracciano | E13: P | I13: NO | J13: NO | L13: 0.9
A14: 1 | B14: Incontro al capitano | C14: 3-5-2 | D14: Bartesaghi | E14: D | F14: 6 | G14: 6 | H14: 0 | I14: NO | J14: SI | K14: Molina N. | L14: 22
A15: 1 | B15: Incontro al capitano | C15: 3-5-2 | D15: Obrador | E15: D | I15: NO | J15: NO | L15: 5
A16: 1 | B16: Incontro al capitano | C16: 3-5-2 | D16: Gabbia | E16: D | F16: 6 | G16: 6 | H16: 0 | I16: NO | J16: NO | L16: 17
A17: 1 | B17: Incontro al capitano | C17: 3-5-2 | D17: Kolasinac | E17: D | F17: 6 | G17: 6 | H17: 0 | I17: NO | J17: NO | L17: 4
A18: 1 | B18: Incontro al capitano | C18: 3-5-2 | D18: Locatelli | E18: C | F18: 6 | G18: 6 | H18: 0 | I18: NO | J18: NO | L18: 25
A19: 1 | B19: Incontro al capitano | C19: 3-5-2 | D19: Fagioli | E19: C | F19: 5 | G19: 4.5 | H19: -0.5 | I19: NO | J19: NO | L19: 16
A20: 1 | B20: Incontro al capitano | C20: 3-5-2 | D20: Oulai | E20: C | F20: 6 | G20: 6 | H20: 0 | I20: NO | J20: NO | L20: 28
A21: 1 | B21: Incontro al capitano | C21: 3-5-2 | D21: Mkhitaryan | E21: C | I21: NO | J21: NO | L21: 3
A22: 1 | B22: Incontro al capitano | C22: 3-5-2 | D22: Vitinha O. | E22: A | F22: 5.5 | G22: 5.5 | H22: 0 | I22: NO | J22: NO | L22: 8
A23: 1 | B23: Incontro al capitano | C23: 3-5-2 | D23: Cutrone | E23: A | F23: 6 | G23: 6 | H23: 0 | I23: NO | J23: NO | L23: 4
A24: 1 | B24: Incontro al capitano | C24: 3-5-2 | D24: Camarda | E24: A | I24: NO | J24: NO | L24: 15
A25: 1 | B25: I Bamboli | C25: 3-5-2 | D25: De Gea | E25: P | F25: 5 | G25: 1 | H25: -4 | I25: SI | J25: SI | L25: 3.5
A26: 1 | B26: I Bamboli | C26: 3-5-2 | D26: Carlos Augusto | E26: D | I26: SI | J26: NO | L26: 23
A27: 1 | B27: I Bamboli | C27: 3-5-2 | D27: Solet | E27: D | F27: 6 | G27: 6 | H27: 0 | I27: SI | J27: SI | L27: 23
A28: 1 | B28: I Bamboli | C28: 3-5-2 | D28: Di Lorenzo | E28: D | F28: 6.5 | G28: 6.5 | H28: 0 | I28: SI | J28: SI | L28: 7.5
A29: 1 | B29: I Bamboli | C29: 3-5-2 | D29: Calò | E29: C | F29: 6 | G29: 6 | H29: 0 | I29: SI | J29: SI | L29: 2.5
A30: 1 | B30: I Bamboli | C30: 3-5-2 | D30: Gaetano | E30: C | F30: 6.5 | G30: 7.5 | H30: 1 | I30: SI | J30: SI | L30: 6.5
A31: 1 | B31: I Bamboli | C31: 3-5-2 | D31: Rabiot | E31: C | F31: 7.5 | G31: 11.5 | H31: 4 | I31: SI | J31: SI | L31: 18
A32: 1 | B32: I Bamboli | C32: 3-5-2 | D32: Calhanoglu | E32: C | F32: 7 | G32: 9.5 | H32: 2.5 | I32: SI | J32: SI | L32: 16
A33: 1 | B33: I Bamboli | C33: 3-5-2 | D33: Pellegrini Lo. | E33: C | I33: SI | J33: NO | L33: 8
A34: 1 | B34: I Bamboli | C34: 3-5-2 | D34: Dia | E34: A | F34: 6.5 | G34: 7 | H34: 0.5 | I34: SI | J34: SI | L34: 5
A35: 1 | B35: I Bamboli | C35: 3-5-2 | D35: Hojlund | E35: A | F35: 5.5 | G35: 5.5 | H35: 0 | I35: SI | J35: SI | L35: 60
A36: 1 | B36: I Bamboli | C36: 3-5-2 | D36: Christensen O. | E36: P | I36: NO | J36: NO | L36: 1.4
A37: 1 | B37: I Bamboli | C37: 3-5-2 | D37: Valeri | E37: D | F37: 6 | G37: 6 | H37: 0 | I37: NO | J37: SI | K37: Carlos Augusto | L37: 3
A38: 1 | B38: I Bamboli | C38: 3-5-2 | D38: Celik | E38: D | F38: 6 | G38: 5.5 | H38: -0.5 | I38: NO | J38: NO | L38: 14
A39: 1 | B39: I Bamboli | C39: 3-5-2 | D39: Gaspar K. | E39: D | F39: 7 | G39: 6.5 | H39: -0.5 | I39: NO | J39: NO | L39: 3
A40: 1 | B40: I Bamboli | C40: 3-5-2 | D40: Obert | E40: D | F40: 6 | G40: 6 | H40: 0 | I40: NO | J40: NO | L40: 7
...

Sheet Analisi Bonus
A1: Analisi BonusMalus per Squadra
A2: Dati cumulati su tutte le giornate presenti nel foglio Database
A4: Squadra | B4: Portieri (VU) | C4: Difensori (VU) | D4: Centrocampisti (VU) | E4: Attaccanti (VU) | F4: Totale Voti Utili | G4: Subentrati | H4: Panchinari (no P)
A5: {=_xlfn._xlws.SORT(_xlfn.UNIQUE(Fantacalcio[Squadra]))} -> Evacuo Kaka Toni | B5: =IF($A5="","",SUMIFS(Fantacalcio[BonusMalus],Fantacalcio[Squadra],$A5,Fantacalcio[VotoUtile],"SI",Fantacalcio[Ruolo],"P")) -> -7 | C5: =IF($A5="","",SUMIFS(Fantacalcio[BonusMalus],Fantacalcio[Squadra],$A5,Fantacalcio[VotoUtile],"SI",Fantacalcio[Ruolo],"D")) -> 10 | D5: =IF($A5="","",SUMIFS(Fantacalcio[BonusMalus],Fantacalcio[Squadra],$A5,Fantacalcio[VotoUtile],"SI",Fantacalcio[Ruolo],"C")) -> 8 | E5: =IF($A5="","",SUMIFS(Fantacalcio[BonusMalus],Fantacalcio[Squadra],$A5,Fantacalcio[VotoUtile],"SI",Fantacalcio[Ruolo],"A")) -> 3.5 | F5: =IF($A5="","",SUMIFS(Fantacalcio[BonusMalus],Fantacalcio[Squadra],$A5,Fantacalcio[VotoUtile],"SI")) -> 14.5 | G5: =IF($A5="","",SUMIFS(Fantacalcio[BonusMalus],Fantacalcio[Squadra],$A5,Fantacalcio[Titolare],"NO",Fantacalcio[VotoUtile],"SI")) -> 1.5 | H5: =IF($A5="","",SUMIFS(Fantacalcio[BonusMalus],Fantacalcio[Squadra],$A5,Fantacalcio[Titolare],"NO",Fantacalcio[VotoUtile],"NO",Fantacalcio[Ruolo],"<>P")) -> 1.5
A6: GC21 | B6: =IF($A6="","",SUMIFS(Fantacalcio[BonusMalus],Fantacalcio[Squadra],$A6,Fantacalcio[VotoUtile],"SI",Fantacalcio[Ruolo],"P")) -> -9 | C6: =IF($A6="","",SUMIFS(Fantacalcio[BonusMalus],Fantacalcio[Squadra],$A6,Fantacalcio[VotoUtile],"SI",Fantacalcio[Ruolo],"D")) -> 7.5 | D6: =IF($A6="","",SUMIFS(Fantacalcio[BonusMalus],Fantacalcio[Squadra],$A6,Fantacalcio[VotoUtile],"SI",Fantacalcio[Ruolo],"C")) -> 11.5 | E6: =IF($A6="","",SUMIFS(Fantacalcio[BonusMalus],Fantacalcio[Squadra],$A6,Fantacalcio[VotoUtile],"SI",Fantacalcio[Ruolo],"A")) -> 16.5 | F6: =IF($A6="","",SUMIFS(Fantacalcio[BonusMalus],Fantacalcio[Squadra],$A6,Fantacalcio[VotoUtile],"SI")) -> 26.5 | G6: =IF($A6="","",SUMIFS(Fantacalcio[BonusMalus],Fantacalcio[Squadra],$A6,Fantacalcio[Titolare],"NO",Fantacalcio[VotoUtile],"SI")) -> 2 | H6: =IF($A6="","",SUMIFS(Fantacalcio[BonusMalus],Fantacalcio[Squadra],$A6,Fantacalcio[Titolare],"NO",Fantacalcio[VotoUtile],"NO",Fantacalcio[Ruolo],"<>P")) -> 12
A7: I Bamboli | B7: =IF($A7="","",SUMIFS(Fantacalcio[BonusMalus],Fantacalcio[Squadra],$A7,Fantacalcio[VotoUtile],"SI",Fantacalcio[Ruolo],"P")) -> -11.5 | C7: =IF($A7="","",SUMIFS(Fantacalcio[BonusMalus],Fantacalcio[Squadra],$A7,Fantacalcio[VotoUtile],"SI",Fantacalcio[Ruolo],"D")) -> 4.5 | D7: =IF($A7="","",SUMIFS(Fantacalcio[BonusMalus],Fantacalcio[Squadra],$A7,Fantacalcio[VotoUtile],"SI",Fantacalcio[Ruolo],"C")) -> 23.5 | E7: =IF($A7="","",SUMIFS(Fantacalcio[BonusMalus],Fantacalcio[Squadra],$A7,Fantacalcio[VotoUtile],"SI",Fantacalcio[Ruolo],"A")) -> 13.5 | F7: =IF($A7="","",SUMIFS(Fantacalcio[BonusMalus],Fantacalcio[Squadra],$A7,Fantacalcio[VotoUtile],"SI")) -> 30 | G7: =IF($A7="","",SUMIFS(Fantacalcio[BonusMalus],Fantacalcio[Squadra],$A7,Fantacalcio[Titolare],"NO",Fantacalcio[VotoUtile],"SI")) -> -2 | H7: =IF($A7="","",SUMIFS(Fantacalcio[BonusMalus],Fantacalcio[Squadra],$A7,Fantacalcio[Titolare],"NO",Fantacalcio[VotoUtile],"NO",Fantacalcio[Ruolo],"<>P")) -> 20
A8: Incontro al capitano | B8: =IF($A8="","",SUMIFS(Fantacalcio[BonusMalus],Fantacalcio[Squadra],$A8,Fantacalcio[VotoUtile],"SI",Fantacalcio[Ruolo],"P")) -> -4 | C8: =IF($A8="","",SUMIFS(Fantacalcio[BonusMalus],Fantacalcio[Squadra],$A8,Fantacalcio[VotoUtile],"SI",Fantacalcio[Ruolo],"D")) -> 7 | D8: =IF($A8="","",SUMIFS(Fantacalcio[BonusMalus],Fantacalcio[Squadra],$A8,Fantacalcio[VotoUtile],"SI",Fantacalcio[Ruolo],"C")) -> 6 | E8: =IF($A8="","",SUMIFS(Fantacalcio[BonusMalus],Fantacalcio[Squadra],$A8,Fantacalcio[VotoUtile],"SI",Fantacalcio[Ruolo],"A")) -> 3 | F8: =IF($A8="","",SUMIFS(Fantacalcio[BonusMalus],Fantacalcio[Squadra],$A8,Fantacalcio[VotoUtile],"SI")) -> 12 | G8: =IF($A8="","",SUMIFS(Fantacalcio[BonusMalus],Fantacalcio[Squadra],$A8,Fantacalcio[Titolare],"NO",Fantacalcio[VotoUtile],"SI")) -> -2.5 | H8: =IF($A8="","",SUMIFS(Fantacalcio[BonusMalus],Fantacalcio[Squadra],$A8,Fantacalcio[Titolare],"NO",Fantacalcio[VotoUtile],"NO",Fantacalcio[Ruolo],"<>P")) -> 3
A9: Mancinix | B9: =IF($A9="","",SUMIFS(Fantacalcio[BonusMalus],Fantacalcio[Squadra],$A9,Fantacalcio[VotoUtile],"SI",Fantacalcio[Ruolo],"P")) -> -6.5 | C9: =IF($A9="","",SUMIFS(Fantacalcio[BonusMalus],Fantacalcio[Squadra],$A9,Fantacalcio[VotoUtile],"SI",Fantacalcio[Ruolo],"D")) -> -0.5 | D9: =IF($A9="","",SUMIFS(Fantacalcio[BonusMalus],Fantacalcio[Squadra],$A9,Fantacalcio[VotoUtile],"SI",Fantacalcio[Ruolo],"C")) -> 8.5 | E9: =IF($A9="","",SUMIFS(Fantacalcio[BonusMalus],Fantacalcio[Squadra],$A9,Fantacalcio[VotoUtile],"SI",Fantacalcio[Ruolo],"A")) -> 19.5 | F9: =IF($A9="","",SUMIFS(Fantacalcio[BonusMalus],Fantacalcio[Squadra],$A9,Fantacalcio[VotoUtile],"SI")) -> 21 | G9: =IF($A9="","",SUMIFS(Fantacalcio[BonusMalus],Fantacalcio[Squadra],$A9,Fantacalcio[Titolare],"NO",Fantacalcio[VotoUtile],"SI")) -> -0.5 | H9: =IF($A9="","",SUMIFS(Fantacalcio[BonusMalus],Fantacalcio[Squadra],$A9,Fantacalcio[Titolare],"NO",Fantacalcio[VotoUtile],"NO",Fantacalcio[Ruolo],"<>P")) -> 15
A10: Masterchef FC | B10: =IF($A10="","",SUMIFS(Fantacalcio[BonusMalus],Fantacalcio[Squadra],$A10,Fantacalcio[VotoUtile],"SI",Fantacalcio[Ruolo],"P")) -> -7 | C10: =IF($A10="","",SUMIFS(Fantacalcio[BonusMalus],Fantacalcio[Squadra],$A10,Fantacalcio[VotoUtile],"SI",Fantacalcio[Ruolo],"D")) -> 8 | D10: =IF($A10="","",SUMIFS(Fantacalcio[BonusMalus],Fantacalcio[Squadra],$A10,Fantacalcio[VotoUtile],"SI",Fantacalcio[Ruolo],"C")) -> 14.5 | E10: =IF($A10="","",SUMIFS(Fantacalcio[BonusMalus],Fantacalcio[Squadra],$A10,Fantacalcio[VotoUtile],"SI",Fantacalcio[Ruolo],"A")) -> 14 | F10: =IF($A10="","",SUMIFS(Fantacalcio[BonusMalus],Fantacalcio[Squadra],$A10,Fantacalcio[VotoUtile],"SI")) -> 29.5 | G10: =IF($A10="","",SUMIFS(Fantacalcio[BonusMalus],Fantacalcio[Squadra],$A10,Fantacalcio[Titolare],"NO",Fantacalcio[VotoUtile],"SI")) -> 6 | H10: =IF($A10="","",SUMIFS(Fantacalcio[BonusMalus],Fantacalcio[Squadra],$A10,Fantacalcio[Titolare],"NO",Fantacalcio[VotoUtile],"NO",Fantacalcio[Ruolo],"<>P")) -> 16
A11: Outletico Palermo | B11: =IF($A11="","",SUMIFS(Fantacalcio[BonusMalus],Fantacalcio[Squadra],$A11,Fantacalcio[VotoUtile],"SI",Fantacalcio[Ruolo],"P")) -> -1 | C11: =IF($A11="","",SUMIFS(Fantacalcio[BonusMalus],Fantacalcio[Squadra],$A11,Fantacalcio[VotoUtile],"SI",Fantacalcio[Ruolo],"D")) -> 1 | D11: =IF($A11="","",SUMIFS(Fantacalcio[BonusMalus],Fantacalcio[Squadra],$A11,Fantacalcio[VotoUtile],"SI",Fantacalcio[Ruolo],"C")) -> 16 | E11: =IF($A11="","",SUMIFS(Fantacalcio[BonusMalus],Fantacalcio[Squadra],$A11,Fantacalcio[VotoUtile],"SI",Fantacalcio[Ruolo],"A")) -> 16.5 | F11: =IF($A11="","",SUMIFS(Fantacalcio[BonusMalus],Fantacalcio[Squadra],$A11,Fantacalcio[VotoUtile],"SI")) -> 32.5 | G11: =IF($A11="","",SUMIFS(Fantacalcio[BonusMalus],Fantacalcio[Squadra],$A11,Fantacalcio[Titolare],"NO",Fantacalcio[VotoUtile],"SI")) -> -0.5 | H11: =IF($A11="","",SUMIFS(Fantacalcio[BonusMalus],Fantacalcio[Squadra],$A11,Fantacalcio[Titolare],"NO",Fantacalcio[VotoUtile],"NO",Fantacalcio[Ruolo],"<>P")) -> 4
A12: Paris Saint-Gervasoni | B12: =IF($A12="","",SUMIFS(Fantacalcio[BonusMalus],Fantacalcio[Squadra],$A12,Fantacalcio[VotoUtile],"SI",Fantacalcio[Ruolo],"P")) -> -4 | C12: =IF($A12="","",SUMIFS(Fantacalcio[BonusMalus],Fantacalcio[Squadra],$A12,Fantacalcio[VotoUtile],"SI",Fantacalcio[Ruolo],"D")) -> 10.5 | D12: =IF($A12="","",SUMIFS(Fantacalcio[BonusMalus],Fantacalcio[Squadra],$A12,Fantacalcio[VotoUtile],"SI",Fantacalcio[Ruolo],"C")) -> 16 | E12: =IF($A12="","",SUMIFS(Fantacalcio[BonusMalus],Fantacalcio[Squadra],$A12,Fantacalcio[VotoUtile],"SI",Fantacalcio[Ruolo],"A")) -> 17.5 | F12: =IF($A12="","",SUMIFS(Fantacalcio[BonusMalus],Fantacalcio[Squadra],$A12,Fantacalcio[VotoUtile],"SI")) -> 40 | G12: =IF($A12="","",SUMIFS(Fantacalcio[BonusMalus],Fantacalcio[Squadra],$A12,Fantacalcio[Titolare],"NO",Fantacalcio[VotoUtile],"SI")) -> 3 | H12: =IF($A12="","",SUMIFS(Fantacalcio[BonusMalus],Fantacalcio[Squadra],$A12,Fantacalcio[Titolare],"NO",Fantacalcio[VotoUtile],"NO",Fantacalcio[Ruolo],"<>P")) -> 18.5
A13: Schalke 104 | B13: =IF($A13="","",SUMIFS(Fantacalcio[BonusMalus],Fantacalcio[Squadra],$A13,Fantacalcio[VotoUtile],"SI",Fantacalcio[Ruolo],"P")) -> -4.5 | C13: =IF($A13="","",SUMIFS(Fantacalcio[BonusMalus],Fantacalcio[Squadra],$A13,Fantacalcio[VotoUtile],"SI",Fantacalcio[Ruolo],"D")) -> 0.5 | D13: =IF($A13="","",SUMIFS(Fantacalcio[BonusMalus],Fantacalcio[Squadra],$A13,Fantacalcio[VotoUtile],"SI",Fantacalcio[Ruolo],"C")) -> 11.5 | E13: =IF($A13="","",SUMIFS(Fantacalcio[BonusMalus],Fantacalcio[Squadra],$A13,Fantacalcio[VotoUtile],"SI",Fantacalcio[Ruolo],"A")) -> 15 | F13: =IF($A13="","",SUMIFS(Fantacalcio[BonusMalus],Fantacalcio[Squadra],$A13,Fantacalcio[VotoUtile],"SI")) -> 22.5 | G13: =IF($A13="","",SUMIFS(Fantacalcio[BonusMalus],Fantacalcio[Squadra],$A13,Fantacalcio[Titolare],"NO",Fantacalcio[VotoUtile],"SI")) -> 0 | H13: =IF($A13="","",SUMIFS(Fantacalcio[BonusMalus],Fantacalcio[Squadra],$A13,Fantacalcio[Titolare],"NO",Fantacalcio[VotoUtile],"NO",Fantacalcio[Ruolo],"<>P")) -> 26
A14: SuperGregariana | B14: =IF($A14="","",SUMIFS(Fantacalcio[BonusMalus],Fantacalcio[Squadra],$A14,Fantacalcio[VotoUtile],"SI",Fantacalcio[Ruolo],"P")) -> -8.5 | C14: =IF($A14="","",SUMIFS(Fantacalcio[BonusMalus],Fantacalcio[Squadra],$A14,Fantacalcio[VotoUtile],"SI",Fantacalcio[Ruolo],"D")) -> -1 | D14: =IF($A14="","",SUMIFS(Fantacalcio[BonusMalus],Fantacalcio[Squadra],$A14,Fantacalcio[VotoUtile],"SI",Fantacalcio[Ruolo],"C")) -> 8.5 | E14: =IF($A14="","",SUMIFS(Fantacalcio[BonusMalus],Fantacalcio[Squadra],$A14,Fantacalcio[VotoUtile],"SI",Fantacalcio[Ruolo],"A")) -> 18 | F14: =IF($A14="","",SUMIFS(Fantacalcio[BonusMalus],Fantacalcio[Squadra],$A14,Fantacalcio[VotoUtile],"SI")) -> 17 | G14: =IF($A14="","",SUMIFS(Fantacalcio[BonusMalus],Fantacalcio[Squadra],$A14,Fantacalcio[Titolare],"NO",Fantacalcio[VotoUtile],"SI")) -> -5 | H14: =IF($A14="","",SUMIFS(Fantacalcio[BonusMalus],Fantacalcio[Squadra],$A14,Fantacalcio[Titolare],"NO",Fantacalcio[VotoUtile],"NO",Fantacalcio[Ruolo],"<>P")) -> 8.5
B15: =IF($A15="","",SUMIFS(Fantacalcio[BonusMalus],Fantacalcio[Squadra],$A15,Fantacalcio[VotoUtile],"SI",Fantacalcio[Ruolo],"P")) | C15: =IF($A15="","",SUMIFS(Fantacalcio[BonusMalus],Fantacalcio[Squadra],$A15,Fantacalcio[VotoUtile],"SI",Fantacalcio[Ruolo],"D")) | D15: =IF($A15="","",SUMIFS(Fantacalcio[BonusMalus],Fantacalcio[Squadra],$A15,Fantacalcio[VotoUtile],"SI",Fantacalcio[Ruolo],"C")) | E15: =IF($A15="","",SUMIFS(Fantacalcio[BonusMalus],Fantacalcio[Squadra],$A15,Fantacalcio[VotoUtile],"SI",Fantacalcio[Ruolo],"A")) | F15: =IF($A15="","",SUMIFS(Fantacalcio[BonusMalus],Fantacalcio[Squadra],$A15,Fantacalcio[VotoUtile],"SI")) | G15: =IF($A15="","",SUMIFS(Fantacalcio[BonusMalus],Fantacalcio[Squadra],$A15,Fantacalcio[Titolare],"NO",Fantacalcio[VotoUtile],"SI")) | H15: =IF($A15="","",SUMIFS(Fantacalcio[BonusMalus],Fantacalcio[Squadra],$A15,Fantacalcio[Titolare],"NO",Fantacalcio[VotoUtile],"NO",Fantacalcio[Ruolo],"<>P"))
B16: =IF($A16="","",SUMIFS(Fantacalcio[BonusMalus],Fantacalcio[Squadra],$A16,Fantacalcio[VotoUtile],"SI",Fantacalcio[Ruolo],"P")) | C16: =IF($A16="","",SUMIFS(Fantacalcio[BonusMalus],Fantacalcio[Squadra],$A16,Fantacalcio[VotoUtile],"SI",Fantacalcio[Ruolo],"D")) | D16: =IF($A16="","",SUMIFS(Fantacalcio[BonusMalus],Fantacalcio[Squadra],$A16,Fantacalcio[VotoUtile],"SI",Fantacalcio[Ruolo],"C")) | E16: =IF($A16="","",SUMIFS(Fantacalcio[BonusMalus],Fantacalcio[Squadra],$A16,Fantacalcio[VotoUtile],"SI",Fantacalcio[Ruolo],"A")) | F16: =IF($A16="","",SUMIFS(Fantacalcio[BonusMalus],Fantacalcio[Squadra],$A16,Fantacalcio[VotoUtile],"SI")) | G16: =IF($A16="","",SUMIFS(Fantacalcio[BonusMalus],Fantacalcio[Squadra],$A16,Fantacalcio[Titolare],"NO",Fantacalcio[VotoUtile],"SI")) | H16: =IF($A16="","",SUMIFS(Fantacalcio[BonusMalus],Fantacalcio[Squadra],$A16,Fantacalcio[Titolare],"NO",Fantacalcio[VotoUtile],"NO",Fantacalcio[Ruolo],"<>P"))
B17: =IF($A17="","",SUMIFS(Fantacalcio[BonusMalus],Fantacalcio[Squadra],$A17,Fantacalcio[VotoUtile],"SI",Fantacalcio[Ruolo],"P")) | C17: =IF($A17="","",SUMIFS(Fantacalcio[BonusMalus],Fantacalcio[Squadra],$A17,Fantacalcio[VotoUtile],"SI",Fantacalcio[Ruolo],"D")) | D17: =IF($A17="","",SUMIFS(Fantacalcio[BonusMalus],Fantacalcio[Squadra],$A17,Fantacalcio[VotoUtile],"SI",Fantacalcio[Ruolo],"C")) | E17: =IF($A17="","",SUMIFS(Fantacalcio[BonusMalus],Fantacalcio[Squadra],$A17,Fantacalcio[VotoUtile],"SI",Fantacalcio[Ruolo],"A")) | F17: =IF($A17="","",SUMIFS(Fantacalcio[BonusMalus],Fantacalcio[Squadra],$A17,Fantacalcio[VotoUtile],"SI")) | G17: =IF($A17="","",SUMIFS(Fantacalcio[BonusMalus],Fantacalcio[Squadra],$A17,Fantacalcio[Titolare],"NO",Fantacalcio[VotoUtile],"SI")) | H17: =IF($A17="","",SUMIFS(Fantacalcio[BonusMalus],Fantacalcio[Squadra],$A17,Fantacalcio[Titolare],"NO",Fantacalcio[VotoUtile],"NO",Fantacalcio[Ruolo],"<>P"))
B18: =IF($A18="","",SUMIFS(Fantacalcio[BonusMalus],Fantacalcio[Squadra],$A18,Fantacalcio[VotoUtile],"SI",Fantacalcio[Ruolo],"P")) | C18: =IF($A18="","",SUMIFS(Fantacalcio[BonusMalus],Fantacalcio[Squadra],$A18,Fantacalcio[VotoUtile],"SI",Fantacalcio[Ruolo],"D")) | D18: =IF($A18="","",SUMIFS(Fantacalcio[BonusMalus],Fantacalcio[Squadra],$A18,Fantacalcio[VotoUtile],"SI",Fantacalcio[Ruolo],"C")) | E18: =IF($A18="","",SUMIFS(Fantacalcio[BonusMalus],Fantacalcio[Squadra],$A18,Fantacalcio[VotoUtile],"SI",Fantacalcio[Ruolo],"A")) | F18: =IF($A18="","",SUMIFS(Fantacalcio[BonusMalus],Fantacalcio[Squadra],$A18,Fantacalcio[VotoUtile],"SI")) | G18: =IF($A18="","",SUMIFS(Fantacalcio[BonusMalus],Fantacalcio[Squadra],$A18,Fantacalcio[Titolare],"NO",Fantacalcio[VotoUtile],"SI")) | H18: =IF($A18="","",SUMIFS(Fantacalcio[BonusMalus],Fantacalcio[Squadra],$A18,Fantacalcio[Titolare],"NO",Fantacalcio[VotoUtile],"NO",Fantacalcio[Ruolo],"<>P"))
B19: =IF($A19="","",SUMIFS(Fantacalcio[BonusMalus],Fantacalcio[Squadra],$A19,Fantacalcio[VotoUtile],"SI",Fantacalcio[Ruolo],"P")) | C19: =IF($A19="","",SUMIFS(Fantacalcio[BonusMalus],Fantacalcio[Squadra],$A19,Fantacalcio[VotoUtile],"SI",Fantacalcio[Ruolo],"D")) | D19: =IF($A19="","",SUMIFS(Fantacalcio[BonusMalus],Fantacalcio[Squadra],$A19,Fantacalcio[VotoUtile],"SI",Fantacalcio[Ruolo],"C")) | E19: =IF($A19="","",SUMIFS(Fantacalcio[BonusMalus],Fantacalcio[Squadra],$A19,Fantacalcio[VotoUtile],"SI",Fantacalcio[Ruolo],"A")) | F19: =IF($A19="","",SUMIFS(Fantacalcio[BonusMalus],Fantacalcio[Squadra],$A19,Fantacalcio[VotoUtile],"SI")) | G19: =IF($A19="","",SUMIFS(Fantacalcio[BonusMalus],Fantacalcio[Squadra],$A19,Fantacalcio[Titolare],"NO",Fantacalcio[VotoUtile],"SI")) | H19: =IF($A19="","",SUMIFS(Fantacalcio[BonusMalus],Fantacalcio[Squadra],$A19,Fantacalcio[Titolare],"NO",Fantacalcio[VotoUtile],"NO",Fantacalcio[Ruolo],"<>P"))
B20: =IF($A20="","",SUMIFS(Fantacalcio[BonusMalus],Fantacalcio[Squadra],$A20,Fantacalcio[VotoUtile],"SI",Fantacalcio[Ruolo],"P")) | C20: =IF($A20="","",SUMIFS(Fantacalcio[BonusMalus],Fantacalcio[Squadra],$A20,Fantacalcio[VotoUtile],"SI",Fantacalcio[Ruolo],"D")) | D20: =IF($A20="","",SUMIFS(Fantacalcio[BonusMalus],Fantacalcio[Squadra],$A20,Fantacalcio[VotoUtile],"SI",Fantacalcio[Ruolo],"C")) | E20: =IF($A20="","",SUMIFS(Fantacalcio[BonusMalus],Fantacalcio[Squadra],$A20,Fantacalcio[VotoUtile],"SI",Fantacalcio[Ruolo],"A")) | F20: =IF($A20="","",SUMIFS(Fantacalcio[BonusMalus],Fantacalcio[Squadra],$A20,Fantacalcio[VotoUtile],"SI")) | G20: =IF($A20="","",SUMIFS(Fantacalcio[BonusMalus],Fantacalcio[Squadra],$A20,Fantacalcio[Titolare],"NO",Fantacalcio[VotoUtile],"SI")) | H20: =IF($A20="","",SUMIFS(Fantacalcio[BonusMalus],Fantacalcio[Squadra],$A20,Fantacalcio[Titolare],"NO",Fantacalcio[VotoUtile],"NO",Fantacalcio[Ruolo],"<>P"))
B21: =IF($A21="","",SUMIFS(Fantacalcio[BonusMalus],Fantacalcio[Squadra],$A21,Fantacalcio[VotoUtile],"SI",Fantacalcio[Ruolo],"P")) | C21: =IF($A21="","",SUMIFS(Fantacalcio[BonusMalus],Fantacalcio[Squadra],$A21,Fantacalcio[VotoUtile],"SI",Fantacalcio[Ruolo],"D")) | D21: =IF($A21="","",SUMIFS(Fantacalcio[BonusMalus],Fantacalcio[Squadra],$A21,Fantacalcio[VotoUtile],"SI",Fantacalcio[Ruolo],"C")) | E21: =IF($A21="","",SUMIFS(Fantacalcio[BonusMalus],Fantacalcio[Squadra],$A21,Fantacalcio[VotoUtile],"SI",Fantacalcio[Ruolo],"A")) | F21: =IF($A21="","",SUMIFS(Fantacalcio[BonusMalus],Fantacalcio[Squadra],$A21,Fantacalcio[VotoUtile],"SI")) | G21: =IF($A21="","",SUMIFS(Fantacalcio[BonusMalus],Fantacalcio[Squadra],$A21,Fantacalcio[Titolare],"NO",Fantacalcio[VotoUtile],"SI")) | H21: =IF($A21="","",SUMIFS(Fantacalcio[BonusMalus],Fantacalcio[Squadra],$A21,Fantacalcio[Titolare],"NO",Fantacalcio[VotoUtile],"NO",Fantacalcio[Ruolo],"<>P"))
B22: =IF($A22="","",SUMIFS(Fantacalcio[BonusMalus],Fantacalcio[Squadra],$A22,Fantacalcio[VotoUtile],"SI",Fantacalcio[Ruolo],"P")) | C22: =IF($A22="","",SUMIFS(Fantacalcio[BonusMalus],Fantacalcio[Squadra],$A22,Fantacalcio[VotoUtile],"SI",Fantacalcio[Ruolo],"D")) | D22: =IF($A22="","",SUMIFS(Fantacalcio[BonusMalus],Fantacalcio[Squadra],$A22,Fantacalcio[VotoUtile],"SI",Fantacalcio[Ruolo],"C")) | E22: =IF($A22="","",SUMIFS(Fantacalcio[BonusMalus],Fantacalcio[Squadra],$A22,Fantacalcio[VotoUtile],"SI",Fantacalcio[Ruolo],"A")) | F22: =IF($A22="","",SUMIFS(Fantacalcio[BonusMalus],Fantacalcio[Squadra],$A22,Fantacalcio[VotoUtile],"SI")) | G22: =IF($A22="","",SUMIFS(Fantacalcio[BonusMalus],Fantacalcio[Squadra],$A22,Fantacalcio[Titolare],"NO",Fantacalcio[VotoUtile],"SI")) | H22: =IF($A22="","",SUMIFS(Fantacalcio[BonusMalus],Fantacalcio[Squadra],$A22,Fantacalcio[Titolare],"NO",Fantacalcio[VotoUtile],"NO",Fantacalcio[Ruolo],"<>P"))
B23: =IF($A23="","",SUMIFS(Fantacalcio[BonusMalus],Fantacalcio[Squadra],$A23,Fantacalcio[VotoUtile],"SI",Fantacalcio[Ruolo],"P")) | C23: =IF($A23="","",SUMIFS(Fantacalcio[BonusMalus],Fantacalcio[Squadra],$A23,Fantacalcio[VotoUtile],"SI",Fantacalcio[Ruolo],"D")) | D23: =IF($A23="","",SUMIFS(Fantacalcio[BonusMalus],Fantacalcio[Squadra],$A23,Fantacalcio[VotoUtile],"SI",Fantacalcio[Ruolo],"C")) | E23: =IF($A23="","",SUMIFS(Fantacalcio[BonusMalus],Fantacalcio[Squadra],$A23,Fantacalcio[VotoUtile],"SI",Fantacalcio[Ruolo],"A")) | F23: =IF($A23="","",SUMIFS(Fantacalcio[BonusMalus],Fantacalcio[Squadra],$A23,Fantacalcio[VotoUtile],"SI")) | G23: =IF($A23="","",SUMIFS(Fantacalcio[BonusMalus],Fantacalcio[Squadra],$A23,Fantacalcio[Titolare],"NO",Fantacalcio[VotoUtile],"SI")) | H23: =IF($A23="","",SUMIFS(Fantacalcio[BonusMalus],Fantacalcio[Squadra],$A23,Fantacalcio[Titolare],"NO",Fantacalcio[VotoUtile],"NO",Fantacalcio[Ruolo],"<>P"))
B24: =IF($A24="","",SUMIFS(Fantacalcio[BonusMalus],Fantacalcio[Squadra],$A24,Fantacalcio[VotoUtile],"SI",Fantacalcio[Ruolo],"P")) | C24: =IF($A24="","",SUMIFS(Fantacalcio[BonusMalus],Fantacalcio[Squadra],$A24,Fantacalcio[VotoUtile],"SI",Fantacalcio[Ruolo],"D")) | D24: =IF($A24="","",SUMIFS(Fantacalcio[BonusMalus],Fantacalcio[Squadra],$A24,Fantacalcio[VotoUtile],"SI",Fantacalcio[Ruolo],"C")) | E24: =IF($A24="","",SUMIFS(Fantacalcio[BonusMalus],Fantacalcio[Squadra],$A24,Fantacalcio[VotoUtile],"SI",Fantacalcio[Ruolo],"A")) | F24: =IF($A24="","",SUMIFS(Fantacalcio[BonusMalus],Fantacalcio[Squadra],$A24,Fantacalcio[VotoUtile],"SI")) | G24: =IF($A24="","",SUMIFS(Fantacalcio[BonusMalus],Fantacalcio[Squadra],$A24,Fantacalcio[Titolare],"NO",Fantacalcio[VotoUtile],"SI")) | H24: =IF($A24="","",SUMIFS(Fantacalcio[BonusMalus],Fantacalcio[Squadra],$A24,Fantacalcio[Titolare],"NO",Fantacalcio[VotoUtile],"NO",Fantacalcio[Ruolo],"<>P"))
A26: Legenda
A27: VU = Voto Utile (colonna VotoUtile = SI)
A28: Portieri/Difensori/Centrocampisti/Attaccanti: BonusMalus dei soli giocatori con Voto Utile, divisi per ruolo
A29: Totale Voti Utili: BonusMalus di tutti i giocatori con Voto Utile (somma delle 4 colonne per ruolo)
A30: Subentrati: Titolare = NO e Voto Utile = SI
A31: Panchinari (no P): Titolare = NO e Voto Utile = NO, portieri esclusi

Sheet Analisi Voto
A1: Analisi Media Voto per Squadra
A2: Dati cumulati su tutte le giornate presenti nel foglio Database
A4: Squadra | B4: Portieri (VU) | C4: Difensori (VU) | D4: Centrocampisti (VU) | E4: Attaccanti (VU) | F4: Media Voti Utili | G4: Subentrati | H4: Panchinari (no P)
A5: {=_xlfn._xlws.SORT(_xlfn.UNIQUE(Fantacalcio[Squadra]))} -> Evacuo Kaka Toni | B5: =IF($A5="","",IFERROR(AVERAGEIFS(Fantacalcio[Voto],Fantacalcio[Squadra],$A5,Fantacalcio[VotoUtile],"SI",Fantacalcio[Ruolo],"P"),"")) -> 6 | C5: =IF($A5="","",IFERROR(AVERAGEIFS(Fantacalcio[Voto],Fantacalcio[Squadra],$A5,Fantacalcio[VotoUtile],"SI",Fantacalcio[Ruolo],"D"),"")) -> 6.0833333 | D5: =IF($A5="","",IFERROR(AVERAGEIFS(Fantacalcio[Voto],Fantacalcio[Squadra],$A5,Fantacalcio[VotoUtile],"SI",Fantacalcio[Ruolo],"C"),"")) -> 6.2 | E5: =IF($A5="","",IFERROR(AVERAGEIFS(Fantacalcio[Voto],Fantacalcio[Squadra],$A5,Fantacalcio[VotoUtile],"SI",Fantacalcio[Ruolo],"A"),"")) -> 5.8888889 | F5: =IF($A5="","",IFERROR(AVERAGEIFS(Fantacalcio[Voto],Fantacalcio[Squadra],$A5,Fantacalcio[VotoUtile],"SI"),"")) -> 6.047619 | G5: =IF($A5="","",IFERROR(AVERAGEIFS(Fantacalcio[Voto],Fantacalcio[Squadra],$A5,Fantacalcio[Titolare],"NO",Fantacalcio[VotoUtile],"SI"),"")) -> 5.9166667 | H5: =IF($A5="","",IFERROR(AVERAGEIFS(Fantacalcio[Voto],Fantacalcio[Squadra],$A5,Fantacalcio[Titolare],"NO",Fantacalcio[VotoUtile],"NO",Fantacalcio[Ruolo],"<>P"),"")) -> 5.8913043
A6: GC21 | B6: =IF($A6="","",IFERROR(AVERAGEIFS(Fantacalcio[Voto],Fantacalcio[Squadra],$A6,Fantacalcio[VotoUtile],"SI",Fantacalcio[Ruolo],"P"),"")) -> 5.8333333 | C6: =IF($A6="","",IFERROR(AVERAGEIFS(Fantacalcio[Voto],Fantacalcio[Squadra],$A6,Fantacalcio[VotoUtile],"SI",Fantacalcio[Ruolo],"D"),"")) -> 6.2142857 | D6: =IF($A6="","",IFERROR(AVERAGEIFS(Fantacalcio[Voto],Fantacalcio[Squadra],$A6,Fantacalcio[VotoUtile],"SI",Fantacalcio[Ruolo],"C"),"")) -> 6.0217391 | E6: =IF($A6="","",IFERROR(AVERAGEIFS(Fantacalcio[Voto],Fantacalcio[Squadra],$A6,Fantacalcio[VotoUtile],"SI",Fantacalcio[Ruolo],"A"),"")) -> 6.09375 | F6: =IF($A6="","",IFERROR(AVERAGEIFS(Fantacalcio[Voto],Fantacalcio[Squadra],$A6,Fantacalcio[VotoUtile],"SI"),"")) -> 6.0833333 | G6: =IF($A6="","",IFERROR(AVERAGEIFS(Fantacalcio[Voto],Fantacalcio[Squadra],$A6,Fantacalcio[Titolare],"NO",Fantacalcio[VotoUtile],"SI"),"")) -> 6 | H6: =IF($A6="","",IFERROR(AVERAGEIFS(Fantacalcio[Voto],Fantacalcio[Squadra],$A6,Fantacalcio[Titolare],"NO",Fantacalcio[VotoUtile],"NO",Fantacalcio[Ruolo],"<>P"),"")) -> 6.0729167
A7: I Bamboli | B7: =IF($A7="","",IFERROR(AVERAGEIFS(Fantacalcio[Voto],Fantacalcio[Squadra],$A7,Fantacalcio[VotoUtile],"SI",Fantacalcio[Ruolo],"P"),"")) -> 5.75 | C7: =IF($A7="","",IFERROR(AVERAGEIFS(Fantacalcio[Voto],Fantacalcio[Squadra],$A7,Fantacalcio[VotoUtile],"SI",Fantacalcio[Ruolo],"D"),"")) -> 6.2222222 | D7: =IF($A7="","",IFERROR(AVERAGEIFS(Fantacalcio[Voto],Fantacalcio[Squadra],$A7,Fantacalcio[VotoUtile],"SI",Fantacalcio[Ruolo],"C"),"")) -> 6.28 | E7: =IF($A7="","",IFERROR(AVERAGEIFS(Fantacalcio[Voto],Fantacalcio[Squadra],$A7,Fantacalcio[VotoUtile],"SI",Fantacalcio[Ruolo],"A"),"")) -> 6.2647059 | F7: =IF($A7="","",IFERROR(AVERAGEIFS(Fantacalcio[Voto],Fantacalcio[Squadra],$A7,Fantacalcio[VotoUtile],"SI"),"")) -> 6.2121212 | G7: =IF($A7="","",IFERROR(AVERAGEIFS(Fantacalcio[Voto],Fantacalcio[Squadra],$A7,Fantacalcio[Titolare],"NO",Fantacalcio[VotoUtile],"SI"),"")) -> 5.5 | H7: =IF($A7="","",IFERROR(AVERAGEIFS(Fantacalcio[Voto],Fantacalcio[Squadra],$A7,Fantacalcio[Titolare],"NO",Fantacalcio[VotoUtile],"NO",Fantacalcio[Ruolo],"<>P"),"")) -> 6.076087
A8: Incontro al capitano | B8: =IF($A8="","",IFERROR(AVERAGEIFS(Fantacalcio[Voto],Fantacalcio[Squadra],$A8,Fantacalcio[VotoUtile],"SI",Fantacalcio[Ruolo],"P"),"")) -> 6.1666667 | C8: =IF($A8="","",IFERROR(AVERAGEIFS(Fantacalcio[Voto],Fantacalcio[Squadra],$A8,Fantacalcio[VotoUtile],"SI",Fantacalcio[Ruolo],"D"),"")) -> 6 | D8: =IF($A8="","",IFERROR(AVERAGEIFS(Fantacalcio[Voto],Fantacalcio[Squadra],$A8,Fantacalcio[VotoUtile],"SI",Fantacalcio[Ruolo],"C"),"")) -> 6.0769231 | E8: =IF($A8="","",IFERROR(AVERAGEIFS(Fantacalcio[Voto],Fantacalcio[Squadra],$A8,Fantacalcio[VotoUtile],"SI",Fantacalcio[Ruolo],"A"),"")) -> 6.2 | F8: =IF($A8="","",IFERROR(AVERAGEIFS(Fantacalcio[Voto],Fantacalcio[Squadra],$A8,Fantacalcio[VotoUtile],"SI"),"")) -> 6.0909091 | G8: =IF($A8="","",IFERROR(AVERAGEIFS(Fantacalcio[Voto],Fantacalcio[Squadra],$A8,Fantacalcio[Titolare],"NO",Fantacalcio[VotoUtile],"SI"),"")) -> 6 | H8: =IF($A8="","",IFERROR(AVERAGEIFS(Fantacalcio[Voto],Fantacalcio[Squadra],$A8,Fantacalcio[Titolare],"NO",Fantacalcio[VotoUtile],"NO",Fantacalcio[Ruolo],"<>P"),"")) -> 5.8636364
A9: Mancinix | B9: =IF($A9="","",IFERROR(AVERAGEIFS(Fantacalcio[Voto],Fantacalcio[Squadra],$A9,Fantacalcio[VotoUtile],"SI",Fantacalcio[Ruolo],"P"),"")) -> 6.5 | C9: =IF($A9="","",IFERROR(AVERAGEIFS(Fantacalcio[Voto],Fantacalcio[Squadra],$A9,Fantacalcio[VotoUtile],"SI",Fantacalcio[Ruolo],"D"),"")) -> 6.0277778 | D9: =IF($A9="","",IFERROR(AVERAGEIFS(Fantacalcio[Voto],Fantacalcio[Squadra],$A9,Fantacalcio[VotoUtile],"SI",Fantacalcio[Ruolo],"C"),"")) -> 6.1153846 | E9: =IF($A9="","",IFERROR(AVERAGEIFS(Fantacalcio[Voto],Fantacalcio[Squadra],$A9,Fantacalcio[VotoUtile],"SI",Fantacalcio[Ruolo],"A"),"")) -> 6.25 | F9: =IF($A9="","",IFERROR(AVERAGEIFS(Fantacalcio[Voto],Fantacalcio[Squadra],$A9,Fantacalcio[VotoUtile],"SI"),"")) -> 6.1590909 | G9: =IF($A9="","",IFERROR(AVERAGEIFS(Fantacalcio[Voto],Fantacalcio[Squadra],$A9,Fantacalcio[Titolare],"NO",Fantacalcio[VotoUtile],"SI"),"")) -> 6.1 | H9: =IF($A9="","",IFERROR(AVERAGEIFS(Fantacalcio[Voto],Fantacalcio[Squadra],$A9,Fantacalcio[Titolare],"NO",Fantacalcio[VotoUtile],"NO",Fantacalcio[Ruolo],"<>P"),"")) -> 6.025
A10: Masterchef FC | B10: =IF($A10="","",IFERROR(AVERAGEIFS(Fantacalcio[Voto],Fantacalcio[Squadra],$A10,Fantacalcio[VotoUtile],"SI",Fantacalcio[Ruolo],"P"),"")) -> 5.5 | C10: =IF($A10="","",IFERROR(AVERAGEIFS(Fantacalcio[Voto],Fantacalcio[Squadra],$A10,Fantacalcio[VotoUtile],"SI",Fantacalcio[Ruolo],"D"),"")) -> 6 | D10: =IF($A10="","",IFERROR(AVERAGEIFS(Fantacalcio[Voto],Fantacalcio[Squadra],$A10,Fantacalcio[VotoUtile],"SI",Fantacalcio[Ruolo],"C"),"")) -> 6 | E10: =IF($A10="","",IFERROR(AVERAGEIFS(Fantacalcio[Voto],Fantacalcio[Squadra],$A10,Fantacalcio[VotoUtile],"SI",Fantacalcio[Ruolo],"A"),"")) -> 5.8611111 | F10: =IF($A10="","",IFERROR(AVERAGEIFS(Fantacalcio[Voto],Fantacalcio[Squadra],$A10,Fantacalcio[VotoUtile],"SI"),"")) -> 5.9166667 | G10: =IF($A10="","",IFERROR(AVERAGEIFS(Fantacalcio[Voto],Fantacalcio[Squadra],$A10,Fantacalcio[Titolare],"NO",Fantacalcio[VotoUtile],"SI"),"")) -> 6.0833333 | H10: =IF($A10="","",IFERROR(AVERAGEIFS(Fantacalcio[Voto],Fantacalcio[Squadra],$A10,Fantacalcio[Titolare],"NO",Fantacalcio[VotoUtile],"NO",Fantacalcio[Ruolo],"<>P"),"")) -> 5.8863636
A11: Outletico Palermo | B11: =IF($A11="","",IFERROR(AVERAGEIFS(Fantacalcio[Voto],Fantacalcio[Squadra],$A11,Fantacalcio[VotoUtile],"SI",Fantacalcio[Ruolo],"P"),"")) -> 6.4166667 | C11: =IF($A11="","",IFERROR(AVERAGEIFS(Fantacalcio[Voto],Fantacalcio[Squadra],$A11,Fantacalcio[VotoUtile],"SI",Fantacalcio[Ruolo],"D"),"")) -> 6.1111111 | D11: =IF($A11="","",IFERROR(AVERAGEIFS(Fantacalcio[Voto],Fantacalcio[Squadra],$A11,Fantacalcio[VotoUtile],"SI",Fantacalcio[Ruolo],"C"),"")) -> 6.0625 | E11: =IF($A11="","",IFERROR(AVERAGEIFS(Fantacalcio[Voto],Fantacalcio[Squadra],$A11,Fantacalcio[VotoUtile],"SI",Fantacalcio[Ruolo],"A"),"")) -> 6.3055556 | F11: =IF($A11="","",IFERROR(AVERAGEIFS(Fantacalcio[Voto],Fantacalcio[Squadra],$A11,Fantacalcio[VotoUtile],"SI"),"")) -> 6.1742424 | G11: =IF($A11="","",IFERROR(AVERAGEIFS(Fantacalcio[Voto],Fantacalcio[Squadra],$A11,Fantacalcio[Titolare],"NO",Fantacalcio[VotoUtile],"SI"),"")) -> 5.7 | H11: =IF($A11="","",IFERROR(AVERAGEIFS(Fantacalcio[Voto],Fantacalcio[Squadra],$A11,Fantacalcio[Titolare],"NO",Fantacalcio[VotoUtile],"NO",Fantacalcio[Ruolo],"<>P"),"")) -> 5.893617
A12: Paris Saint-Gervasoni | B12: =IF($A12="","",IFERROR(AVERAGEIFS(Fantacalcio[Voto],Fantacalcio[Squadra],$A12,Fantacalcio[VotoUtile],"SI",Fantacalcio[Ruolo],"P"),"")) -> 6.4166667 | C12: =IF($A12="","",IFERROR(AVERAGEIFS(Fantacalcio[Voto],Fantacalcio[Squadra],$A12,Fantacalcio[VotoUtile],"SI",Fantacalcio[Ruolo],"D"),"")) -> 6.1111111 | D12: =IF($A12="","",IFERROR(AVERAGEIFS(Fantacalcio[Voto],Fantacalcio[Squadra],$A12,Fantacalcio[VotoUtile],"SI",Fantacalcio[Ruolo],"C"),"")) -> 6.3076923 | E12: =IF($A12="","",IFERROR(AVERAGEIFS(Fantacalcio[Voto],Fantacalcio[Squadra],$A12,Fantacalcio[VotoUtile],"SI",Fantacalcio[Ruolo],"A"),"")) -> 6.09375 | F12: =IF($A12="","",IFERROR(AVERAGEIFS(Fantacalcio[Voto],Fantacalcio[Squadra],$A12,Fantacalcio[VotoUtile],"SI"),"")) -> 6.2121212 | G12: =IF($A12="","",IFERROR(AVERAGEIFS(Fantacalcio[Voto],Fantacalcio[Squadra],$A12,Fantacalcio[Titolare],"NO",Fantacalcio[VotoUtile],"SI"),"")) -> 6.1875 | H12: =IF($A12="","",IFERROR(AVERAGEIFS(Fantacalcio[Voto],Fantacalcio[Squadra],$A12,Fantacalcio[Titolare],"NO",Fantacalcio[VotoUtile],"NO",Fantacalcio[Ruolo],"<>P"),"")) -> 6.0675676
A13: Schalke 104 | B13: =IF($A13="","",IFERROR(AVERAGEIFS(Fantacalcio[Voto],Fantacalcio[Squadra],$A13,Fantacalcio[VotoUtile],"SI",Fantacalcio[Ruolo],"P"),"")) -> 6.1666667 | C13: =IF($A13="","",IFERROR(AVERAGEIFS(Fantacalcio[Voto],Fantacalcio[Squadra],$A13,Fantacalcio[VotoUtile],"SI",Fantacalcio[Ruolo],"D"),"")) -> 6.1388889 | D13: =IF($A13="","",IFERROR(AVERAGEIFS(Fantacalcio[Voto],Fantacalcio[Squadra],$A13,Fantacalcio[VotoUtile],"SI",Fantacalcio[Ruolo],"C"),"")) -> 6.0416667 | E13: =IF($A13="","",IFERROR(AVERAGEIFS(Fantacalcio[Voto],Fantacalcio[Squadra],$A13,Fantacalcio[VotoUtile],"SI",Fantacalcio[Ruolo],"A"),"")) -> 5.9722222 | F13: =IF($A13="","",IFERROR(AVERAGEIFS(Fantacalcio[Voto],Fantacalcio[Squadra],$A13,Fantacalcio[VotoUtile],"SI"),"")) -> 6.0606061 | G13: =IF($A13="","",IFERROR(AVERAGEIFS(Fantacalcio[Voto],Fantacalcio[Squadra],$A13,Fantacalcio[Titolare],"NO",Fantacalcio[VotoUtile],"SI"),"")) -> 6 | H13: =IF($A13="","",IFERROR(AVERAGEIFS(Fantacalcio[Voto],Fantacalcio[Squadra],$A13,Fantacalcio[Titolare],"NO",Fantacalcio[VotoUtile],"NO",Fantacalcio[Ruolo],"<>P"),"")) -> 5.9673913
A14: SuperGregariana | B14: =IF($A14="","",IFERROR(AVERAGEIFS(Fantacalcio[Voto],Fantacalcio[Squadra],$A14,Fantacalcio[VotoUtile],"SI",Fantacalcio[Ruolo],"P"),"")) -> 6.0833333 | C14: =IF($A14="","",IFERROR(AVERAGEIFS(Fantacalcio[Voto],Fantacalcio[Squadra],$A14,Fantacalcio[VotoUtile],"SI",Fantacalcio[Ruolo],"D"),"")) -> 5.8333333 | D14: =IF($A14="","",IFERROR(AVERAGEIFS(Fantacalcio[Voto],Fantacalcio[Squadra],$A14,Fantacalcio[VotoUtile],"SI",Fantacalcio[Ruolo],"C"),"")) -> 5.9791667 | E14: =IF($A14="","",IFERROR(AVERAGEIFS(Fantacalcio[Voto],Fantacalcio[Squadra],$A14,Fantacalcio[VotoUtile],"SI",Fantacalcio[Ruolo],"A"),"")) -> 6.0833333 | F14: =IF($A14="","",IFERROR(AVERAGEIFS(Fantacalcio[Voto],Fantacalcio[Squadra],$A14,Fantacalcio[VotoUtile],"SI"),"")) -> 5.9772727 | G14: =IF($A14="","",IFERROR(AVERAGEIFS(Fantacalcio[Voto],Fantacalcio[Squadra],$A14,Fantacalcio[Titolare],"NO",Fantacalcio[VotoUtile],"SI"),"")) -> 5.7142857 | H14: =IF($A14="","",IFERROR(AVERAGEIFS(Fantacalcio[Voto],Fantacalcio[Squadra],$A14,Fantacalcio[Titolare],"NO",Fantacalcio[VotoUtile],"NO",Fantacalcio[Ruolo],"<>P"),"")) -> 5.872093
A26: Legenda
A27: VU = Voto Utile (colonna VotoUtile = SI)
A28: Portieri/Difensori/Centrocampisti/Attaccanti: media del Voto (non Fantavoto) dei soli giocatori con Voto Utile, divisi per ruolo
A29: Media Voti Utili: media del Voto di tutti i giocatori con Voto Utile
A30: Subentrati: media del Voto dei giocatori con Titolare = NO e Voto Utile = SI
A31: Panchinari (no P): media del Voto dei giocatori con Titolare = NO e Voto Utile = NO, portieri esclusi
A32: I giocatori senza voto (s.v. / non scesi in campo) sono esclusi dalle medie. Cella vuota = nessun giocatore nella categoria.

Sheet Analisi VdM
A1: Analisi Valore di Mercato per Squadra e Giornata
A2: Somma dei VdM (mln €) dei giocatori con Voto Utile = SI. Le giornate senza dati restano vuote ed escluse dalla media.
A4: Squadra | B4: Media | C4: {=_xlfn.SEQUENCE(1,38)} -> 1 | D4: 2 | E4: 3 | F4: 4 | G4: 5 | H4: 6 | I4: 7 | J4: 8 | K4: 9 | L4: 10 | M4: 11 | N4: 12 | O4: 13 | P4: 14 | Q4: 15 | R4: 16 | S4: 17 | T4: 18 | U4: 19 | V4: 20 | W4: 21 | X4: 22 | Y4: 23 | Z4: 24 | AA4: 25 | AB4: 26 | AC4: 27 | AD4: 28 | AE4: 29 | AF4: 30 | AG4: 31 | AH4: 32 | AI4: 33 | AJ4: 34 | AK4: 35 | AL4: 36 | AM4: 37 | AN4: 38
A5: {=_xlfn._xlws.SORT(_xlfn.UNIQUE(_xlfn._xlws.FILTER(Fantacalcio[Squadra],Fantacalcio[Squadra]<>"")))} -> Evacuo Kaka Toni | B5: =IF($A5="","",IF(COUNT(C5:AN5)=0,"",AVERAGE(C5:AN5))) -> 157.83333 | C5: =IF($A5="","",IF(COUNTIFS(Fantacalcio[Giornata],C$4,Fantacalcio[Squadra],$A5)=0,"",SUMIFS(Fantacalcio[VdM (mln €)],Fantacalcio[Giornata],C$4,Fantacalcio[Squadra],$A5,Fantacalcio[VotoUtile],"SI"))) -> 152 | D5: =IF($A5="","",IF(COUNTIFS(Fantacalcio[Giornata],D$4,Fantacalcio[Squadra],$A5)=0,"",SUMIFS(Fantacalcio[VdM (mln €)],Fantacalcio[Giornata],D$4,Fantacalcio[Squadra],$A5,Fantacalcio[VotoUtile],"SI"))) -> 121.4 | E5: =IF($A5="","",IF(COUNTIFS(Fantacalcio[Giornata],E$4,Fantacalcio[Squadra],$A5)=0,"",SUMIFS(Fantacalcio[VdM (mln €)],Fantacalcio[Giornata],E$4,Fantacalcio[Squadra],$A5,Fantacalcio[VotoUtile],"SI"))) -> 128.9 | F5: =IF($A5="","",IF(COUNTIFS(Fantacalcio[Giornata],F$4,Fantacalcio[Squadra],$A5)=0,"",SUMIFS(Fantacalcio[VdM (mln €)],Fantacalcio[Giornata],F$4,Fantacalcio[Squadra],$A5,Fantacalcio[VotoUtile],"SI"))) -> 177.9 | G5: =IF($A5="","",IF(COUNTIFS(Fantacalcio[Giornata],G$4,Fantacalcio[Squadra],$A5)=0,"",SUMIFS(Fantacalcio[VdM (mln €)],Fantacalcio[Giornata],G$4,Fantacalcio[Squadra],$A5,Fantacalcio[VotoUtile],"SI"))) -> 192.9 | H5: =IF($A5="","",IF(COUNTIFS(Fantacalcio[Giornata],H$4,Fantacalcio[Squadra],$A5)=0,"",SUMIFS(Fantacalcio[VdM (mln €)],Fantacalcio[Giornata],H$4,Fantacalcio[Squadra],$A5,Fantacalcio[VotoUtile],"SI"))) -> 173.9 | I5: =IF($A5="","",IF(COUNTIFS(Fantacalcio[Giornata],I$4,Fantacalcio[Squadra],$A5)=0,"",SUMIFS(Fantacalcio[VdM (mln €)],Fantacalcio[Giornata],I$4,Fantacalcio[Squadra],$A5,Fantacalcio[VotoUtile],"SI"))) | J5: =IF($A5="","",IF(COUNTIFS(Fantacalcio[Giornata],J$4,Fantacalcio[Squadra],$A5)=0,"",SUMIFS(Fantacalcio[VdM (mln €)],Fantacalcio[Giornata],J$4,Fantacalcio[Squadra],$A5,Fantacalcio[VotoUtile],"SI"))) | ... AN5: =IF($A5="","",IF(COUNTIFS(Fantacalcio[Giornata],AN$4,Fantacalcio[Squadra],$A5)=0,"",SUMIFS(Fantacalcio[VdM (mln €)],Fantacalcio[Giornata],AN$4,Fantacalcio[Squadra],$A5,Fantacalcio[VotoUtile],"SI")))
A6: GC21 | B6: =IF($A6="","",IF(COUNT(C6:AN6)=0,"",AVERAGE(C6:AN6))) -> 300.83333 | C6: =IF($A6="","",IF(COUNTIFS(Fantacalcio[Giornata],C$4,Fantacalcio[Squadra],$A6)=0,"",SUMIFS(Fantacalcio[VdM (mln €)],Fantacalcio[Giornata],C$4,Fantacalcio[Squadra],$A6,Fantacalcio[VotoUtile],"SI"))) -> 383 | D6: =IF($A6="","",IF(COUNTIFS(Fantacalcio[Giornata],D$4,Fantacalcio[Squadra],$A6)=0,"",SUMIFS(Fantacalcio[VdM (mln €)],Fantacalcio[Giornata],D$4,Fantacalcio[Squadra],$A6,Fantacalcio[VotoUtile],"SI"))) -> 306 | E6: =IF($A6="","",IF(COUNTIFS(Fantacalcio[Giornata],E$4,Fantacalcio[Squadra],$A6)=0,"",SUMIFS(Fantacalcio[VdM (mln €)],Fantacalcio[Giornata],E$4,Fantacalcio[Squadra],$A6,Fantacalcio[VotoUtile],"SI"))) -> 255 | F6: =IF($A6="","",IF(COUNTIFS(Fantacalcio[Giornata],F$4,Fantacalcio[Squadra],$A6)=0,"",SUMIFS(Fantacalcio[VdM (mln €)],Fantacalcio[Giornata],F$4,Fantacalcio[Squadra],$A6,Fantacalcio[VotoUtile],"SI"))) -> 262 | G6: =IF($A6="","",IF(COUNTIFS(Fantacalcio[Giornata],G$4,Fantacalcio[Squadra],$A6)=0,"",SUMIFS(Fantacalcio[VdM (mln €)],Fantacalcio[Giornata],G$4,Fantacalcio[Squadra],$A6,Fantacalcio[VotoUtile],"SI"))) -> 276.5 | H6: =IF($A6="","",IF(COUNTIFS(Fantacalcio[Giornata],H$4,Fantacalcio[Squadra],$A6)=0,"",SUMIFS(Fantacalcio[VdM (mln €)],Fantacalcio[Giornata],H$4,Fantacalcio[Squadra],$A6,Fantacalcio[VotoUtile],"SI"))) -> 322.5 | I6: =IF($A6="","",IF(COUNTIFS(Fantacalcio[Giornata],I$4,Fantacalcio[Squadra],$A6)=0,"",SUMIFS(Fantacalcio[VdM (mln €)],Fantacalcio[Giornata],I$4,Fantacalcio[Squadra],$A6,Fantacalcio[VotoUtile],"SI"))) | J6: =IF($A6="","",IF(COUNTIFS(Fantacalcio[Giornata],J$4,Fantacalcio[Squadra],$A6)=0,"",SUMIFS(Fantacalcio[VdM (mln €)],Fantacalcio[Giornata],J$4,Fantacalcio[Squadra],$A6,Fantacalcio[VotoUtile],"SI"))) | ... AN6: =IF($A6="","",IF(COUNTIFS(Fantacalcio[Giornata],AN$4,Fantacalcio[Squadra],$A6)=0,"",SUMIFS(Fantacalcio[VdM (mln €)],Fantacalcio[Giornata],AN$4,Fantacalcio[Squadra],$A6,Fantacalcio[VotoUtile],"SI")))
A7: I Bamboli | B7: =IF($A7="","",IF(COUNT(C7:AN7)=0,"",AVERAGE(C7:AN7))) -> 174.75 | C7: =IF($A7="","",IF(COUNTIFS(Fantacalcio[Giornata],C$4,Fantacalcio[Squadra],$A7)=0,"",SUMIFS(Fantacalcio[VdM (mln €)],Fantacalcio[Giornata],C$4,Fantacalcio[Squadra],$A7,Fantacalcio[VotoUtile],"SI"))) -> 165 | D7: =IF($A7="","",IF(COUNTIFS(Fantacalcio[Giornata],D$4,Fantacalcio[Squadra],$A7)=0,"",SUMIFS(Fantacalcio[VdM (mln €)],Fantacalcio[Giornata],D$4,Fantacalcio[Squadra],$A7,Fantacalcio[VotoUtile],"SI"))) -> 166 | E7: =IF($A7="","",IF(COUNTIFS(Fantacalcio[Giornata],E$4,Fantacalcio[Squadra],$A7)=0,"",SUMIFS(Fantacalcio[VdM (mln €)],Fantacalcio[Giornata],E$4,Fantacalcio[Squadra],$A7,Fantacalcio[VotoUtile],"SI"))) -> 157.5 | F7: =IF($A7="","",IF(COUNTIFS(Fantacalcio[Giornata],F$4,Fantacalcio[Squadra],$A7)=0,"",SUMIFS(Fantacalcio[VdM (mln €)],Fantacalcio[Giornata],F$4,Fantacalcio[Squadra],$A7,Fantacalcio[VotoUtile],"SI"))) -> 197.5 | G7: =IF($A7="","",IF(COUNTIFS(Fantacalcio[Giornata],G$4,Fantacalcio[Squadra],$A7)=0,"",SUMIFS(Fantacalcio[VdM (mln €)],Fantacalcio[Giornata],G$4,Fantacalcio[Squadra],$A7,Fantacalcio[VotoUtile],"SI"))) -> 183 | H7: =IF($A7="","",IF(COUNTIFS(Fantacalcio[Giornata],H$4,Fantacalcio[Squadra],$A7)=0,"",SUMIFS(Fantacalcio[VdM (mln €)],Fantacalcio[Giornata],H$4,Fantacalcio[Squadra],$A7,Fantacalcio[VotoUtile],"SI"))) -> 179.5 | I7: =IF($A7="","",IF(COUNTIFS(Fantacalcio[Giornata],I$4,Fantacalcio[Squadra],$A7)=0,"",SUMIFS(Fantacalcio[VdM (mln €)],Fantacalcio[Giornata],I$4,Fantacalcio[Squadra],$A7,Fantacalcio[VotoUtile],"SI"))) | J7: =IF($A7="","",IF(COUNTIFS(Fantacalcio[Giornata],J$4,Fantacalcio[Squadra],$A7)=0,"",SUMIFS(Fantacalcio[VdM (mln €)],Fantacalcio[Giornata],J$4,Fantacalcio[Squadra],$A7,Fantacalcio[VotoUtile],"SI"))) | ... AN7: =IF($A7="","",IF(COUNTIFS(Fantacalcio[Giornata],AN$4,Fantacalcio[Squadra],$A7)=0,"",SUMIFS(Fantacalcio[VdM (mln €)],Fantacalcio[Giornata],AN$4,Fantacalcio[Squadra],$A7,Fantacalcio[VotoUtile],"SI")))
A8: Incontro al capitano | B8: =IF($A8="","",IF(COUNT(C8:AN8)=0,"",AVERAGE(C8:AN8))) -> 251.83333 | C8: =IF($A8="","",IF(COUNTIFS(Fantacalcio[Giornata],C$4,Fantacalcio[Squadra],$A8)=0,"",SUMIFS(Fantacalcio[VdM (mln €)],Fantacalcio[Giornata],C$4,Fantacalcio[Squadra],$A8,Fantacalcio[VotoUtile],"SI"))) -> 234.5 | D8: =IF($A8="","",IF(COUNTIFS(Fantacalcio[Giornata],D$4,Fantacalcio[Squadra],$A8)=0,"",SUMIFS(Fantacalcio[VdM (mln €)],Fantacalcio[Giornata],D$4,Fantacalcio[Squadra],$A8,Fantacalcio[VotoUtile],"SI"))) -> 266.5 | E8: =IF($A8="","",IF(COUNTIFS(Fantacalcio[Giornata],E$4,Fantacalcio[Squadra],$A8)=0,"",SUMIFS(Fantacalcio[VdM (mln €)],Fantacalcio[Giornata],E$4,Fantacalcio[Squadra],$A8,Fantacalcio[VotoUtile],"SI"))) -> 252.5 | F8: =IF($A8="","",IF(COUNTIFS(Fantacalcio[Giornata],F$4,Fantacalcio[Squadra],$A8)=0,"",SUMIFS(Fantacalcio[VdM (mln €)],Fantacalcio[Giornata],F$4,Fantacalcio[Squadra],$A8,Fantacalcio[VotoUtile],"SI"))) -> 256.5 | G8: =IF($A8="","",IF(COUNTIFS(Fantacalcio[Giornata],G$4,Fantacalcio[Squadra],$A8)=0,"",SUMIFS(Fantacalcio[VdM (mln €)],Fantacalcio[Giornata],G$4,Fantacalcio[Squadra],$A8,Fantacalcio[VotoUtile],"SI"))) -> 248.5 | H8: =IF($A8="","",IF(COUNTIFS(Fantacalcio[Giornata],H$4,Fantacalcio[Squadra],$A8)=0,"",SUMIFS(Fantacalcio[VdM (mln €)],Fantacalcio[Giornata],H$4,Fantacalcio[Squadra],$A8,Fantacalcio[VotoUtile],"SI"))) -> 252.5 | I8: =IF($A8="","",IF(COUNTIFS(Fantacalcio[Giornata],I$4,Fantacalcio[Squadra],$A8)=0,"",SUMIFS(Fantacalcio[VdM (mln €)],Fantacalcio[Giornata],I$4,Fantacalcio[Squadra],$A8,Fantacalcio[VotoUtile],"SI"))) | J8: =IF($A8="","",IF(COUNTIFS(Fantacalcio[Giornata],J$4,Fantacalcio[Squadra],$A8)=0,"",SUMIFS(Fantacalcio[VdM (mln €)],Fantacalcio[Giornata],J$4,Fantacalcio[Squadra],$A8,Fantacalcio[VotoUtile],"SI"))) | ... AN8: =IF($A8="","",IF(COUNTIFS(Fantacalcio[Giornata],AN$4,Fantacalcio[Squadra],$A8)=0,"",SUMIFS(Fantacalcio[VdM (mln €)],Fantacalcio[Giornata],AN$4,Fantacalcio[Squadra],$A8,Fantacalcio[VotoUtile],"SI")))
A9: Mancinix | B9: =IF($A9="","",IF(COUNT(C9:AN9)=0,"",AVERAGE(C9:AN9))) -> 306.08333 | C9: =IF($A9="","",IF(COUNTIFS(Fantacalcio[Giornata],C$4,Fantacalcio[Squadra],$A9)=0,"",SUMIFS(Fantacalcio[VdM (mln €)],Fantacalcio[Giornata],C$4,Fantacalcio[Squadra],$A9,Fantacalcio[VotoUtile],"SI"))) -> 324 | D9: =IF($A9="","",IF(COUNTIFS(Fantacalcio[Giornata],D$4,Fantacalcio[Squadra],$A9)=0,"",SUMIFS(Fantacalcio[VdM (mln €)],Fantacalcio[Giornata],D$4,Fantacalcio[Squadra],$A9,Fantacalcio[VotoUtile],"SI"))) -> 297 | E9: =IF($A9="","",IF(COUNTIFS(Fantacalcio[Giornata],E$4,Fantacalcio[Squadra],$A9)=0,"",SUMIFS(Fantacalcio[VdM (mln €)],Fantacalcio[Giornata],E$4,Fantacalcio[Squadra],$A9,Fantacalcio[VotoUtile],"SI"))) -> 294 | F9: =IF($A9="","",IF(COUNTIFS(Fantacalcio[Giornata],F$4,Fantacalcio[Squadra],$A9)=0,"",SUMIFS(Fantacalcio[VdM (mln €)],Fantacalcio[Giornata],F$4,Fantacalcio[Squadra],$A9,Fantacalcio[VotoUtile],"SI"))) -> 299.5 | G9: =IF($A9="","",IF(COUNTIFS(Fantacalcio[Giornata],G$4,Fantacalcio[Squadra],$A9)=0,"",SUMIFS(Fantacalcio[VdM (mln €)],Fantacalcio[Giornata],G$4,Fantacalcio[Squadra],$A9,Fantacalcio[VotoUtile],"SI"))) -> 330 | H9: =IF($A9="","",IF(COUNTIFS(Fantacalcio[Giornata],H$4,Fantacalcio[Squadra],$A9)=0,"",SUMIFS(Fantacalcio[VdM (mln €)],Fantacalcio[Giornata],H$4,Fantacalcio[Squadra],$A9,Fantacalcio[VotoUtile],"SI"))) -> 292 | I9: =IF($A9="","",IF(COUNTIFS(Fantacalcio[Giornata],I$4,Fantacalcio[Squadra],$A9)=0,"",SUMIFS(Fantacalcio[VdM (mln €)],Fantacalcio[Giornata],I$4,Fantacalcio[Squadra],$A9,Fantacalcio[VotoUtile],"SI"))) | J9: =IF($A9="","",IF(COUNTIFS(Fantacalcio[Giornata],J$4,Fantacalcio[Squadra],$A9)=0,"",SUMIFS(Fantacalcio[VdM (mln €)],Fantacalcio[Giornata],J$4,Fantacalcio[Squadra],$A9,Fantacalcio[VotoUtile],"SI"))) | ... AN9: =IF($A9="","",IF(COUNTIFS(Fantacalcio[Giornata],AN$4,Fantacalcio[Squadra],$A9)=0,"",SUMIFS(Fantacalcio[VdM (mln €)],Fantacalcio[Giornata],AN$4,Fantacalcio[Squadra],$A9,Fantacalcio[VotoUtile],"SI")))
A10: Masterchef FC | B10: =IF($A10="","",IF(COUNT(C10:AN10)=0,"",AVERAGE(C10:AN10))) -> 203 | C10: =IF($A10="","",IF(COUNTIFS(Fantacalcio[Giornata],C$4,Fantacalcio[Squadra],$A10)=0,"",SUMIFS(Fantacalcio[VdM (mln €)],Fantacalcio[Giornata],C$4,Fantacalcio[Squadra],$A10,Fantacalcio[VotoUtile],"SI"))) -> 209.5 | D10: =IF($A10="","",IF(COUNTIFS(Fantacalcio[Giornata],D$4,Fantacalcio[Squadra],$A10)=0,"",SUMIFS(Fantacalcio[VdM (mln €)],Fantacalcio[Giornata],D$4,Fantacalcio[Squadra],$A10,Fantacalcio[VotoUtile],"SI"))) -> 182 | E10: =IF($A10="","",IF(COUNTIFS(Fantacalcio[Giornata],E$4,Fantacalcio[Squadra],$A10)=0,"",SUMIFS(Fantacalcio[VdM (mln €)],Fantacalcio[Giornata],E$4,Fantacalcio[Squadra],$A10,Fantacalcio[VotoUtile],"SI"))) -> 223.5 | F10: =IF($A10="","",IF(COUNTIFS(Fantacalcio[Giornata],F$4,Fantacalcio[Squadra],$A10)=0,"",SUMIFS(Fantacalcio[VdM (mln €)],Fantacalcio[Giornata],F$4,Fantacalcio[Squadra],$A10,Fantacalcio[VotoUtile],"SI"))) -> 154.5 | G10: =IF($A10="","",IF(COUNTIFS(Fantacalcio[Giornata],G$4,Fantacalcio[Squadra],$A10)=0,"",SUMIFS(Fantacalcio[VdM (mln €)],Fantacalcio[Giornata],G$4,Fantacalcio[Squadra],$A10,Fantacalcio[VotoUtile],"SI"))) -> 178.5 | H10: =IF($A10="","",IF(COUNTIFS(Fantacalcio[Giornata],H$4,Fantacalcio[Squadra],$A10)=0,"",SUMIFS(Fantacalcio[VdM (mln €)],Fantacalcio[Giornata],H$4,Fantacalcio[Squadra],$A10,Fantacalcio[VotoUtile],"SI"))) -> 270 | I10: =IF($A10="","",IF(COUNTIFS(Fantacalcio[Giornata],I$4,Fantacalcio[Squadra],$A10)=0,"",SUMIFS(Fantacalcio[VdM (mln €)],Fantacalcio[Giornata],I$4,Fantacalcio[Squadra],$A10,Fantacalcio[VotoUtile],"SI"))) | J10: =IF($A10="","",IF(COUNTIFS(Fantacalcio[Giornata],J$4,Fantacalcio[Squadra],$A10)=0,"",SUMIFS(Fantacalcio[VdM (mln €)],Fantacalcio[Giornata],J$4,Fantacalcio[Squadra],$A10,Fantacalcio[VotoUtile],"SI"))) | ... AN10: =IF($A10="","",IF(COUNTIFS(Fantacalcio[Giornata],AN$4,Fantacalcio[Squadra],$A10)=0,"",SUMIFS(Fantacalcio[VdM (mln €)],Fantacalcio[Giornata],AN$4,Fantacalcio[Squadra],$A10,Fantacalcio[VotoUtile],"SI")))
A11: Outletico Palermo | B11: =IF($A11="","",IF(COUNT(C11:AN11)=0,"",AVERAGE(C11:AN11))) -> 266.88333 | C11: =IF($A11="","",IF(COUNTIFS(Fantacalcio[Giornata],C$4,Fantacalcio[Squadra],$A11)=0,"",SUMIFS(Fantacalcio[VdM (mln €)],Fantacalcio[Giornata],C$4,Fantacalcio[Squadra],$A11,Fantacalcio[VotoUtile],"SI"))) -> 305 | D11: =IF($A11="","",IF(COUNTIFS(Fantacalcio[Giornata],D$4,Fantacalcio[Squadra],$A11)=0,"",SUMIFS(Fantacalcio[VdM (mln €)],Fantacalcio[Giornata],D$4,Fantacalcio[Squadra],$A11,Fantacalcio[VotoUtile],"SI"))) -> 271 | E11: =IF($A11="","",IF(COUNTIFS(Fantacalcio[Giornata],E$4,Fantacalcio[Squadra],$A11)=0,"",SUMIFS(Fantacalcio[VdM (mln €)],Fantacalcio[Giornata],E$4,Fantacalcio[Squadra],$A11,Fantacalcio[VotoUtile],"SI"))) -> 290 | F11: =IF($A11="","",IF(COUNTIFS(Fantacalcio[Giornata],F$4,Fantacalcio[Squadra],$A11)=0,"",SUMIFS(Fantacalcio[VdM (mln €)],Fantacalcio[Giornata],F$4,Fantacalcio[Squadra],$A11,Fantacalcio[VotoUtile],"SI"))) -> 256 | G11: =IF($A11="","",IF(COUNTIFS(Fantacalcio[Giornata],G$4,Fantacalcio[Squadra],$A11)=0,"",SUMIFS(Fantacalcio[VdM (mln €)],Fantacalcio[Giornata],G$4,Fantacalcio[Squadra],$A11,Fantacalcio[VotoUtile],"SI"))) -> 283 | H11: =IF($A11="","",IF(COUNTIFS(Fantacalcio[Giornata],H$4,Fantacalcio[Squadra],$A11)=0,"",SUMIFS(Fantacalcio[VdM (mln €)],Fantacalcio[Giornata],H$4,Fantacalcio[Squadra],$A11,Fantacalcio[VotoUtile],"SI"))) -> 196.3 | I11: =IF($A11="","",IF(COUNTIFS(Fantacalcio[Giornata],I$4,Fantacalcio[Squadra],$A11)=0,"",SUMIFS(Fantacalcio[VdM (mln €)],Fantacalcio[Giornata],I$4,Fantacalcio[Squadra],$A11,Fantacalcio[VotoUtile],"SI"))) | J11: =IF($A11="","",IF(COUNTIFS(Fantacalcio[Giornata],J$4,Fantacalcio[Squadra],$A11)=0,"",SUMIFS(Fantacalcio[VdM (mln €)],Fantacalcio[Giornata],J$4,Fantacalcio[Squadra],$A11,Fantacalcio[VotoUtile],"SI"))) | ... AN11: =IF($A11="","",IF(COUNTIFS(Fantacalcio[Giornata],AN$4,Fantacalcio[Squadra],$A11)=0,"",SUMIFS(Fantacalcio[VdM (mln €)],Fantacalcio[Giornata],AN$4,Fantacalcio[Squadra],$A11,Fantacalcio[VotoUtile],"SI")))
A12: Paris Saint-Gervasoni | B12: =IF($A12="","",IF(COUNT(C12:AN12)=0,"",AVERAGE(C12:AN12))) -> 190.16667 | C12: =IF($A12="","",IF(COUNTIFS(Fantacalcio[Giornata],C$4,Fantacalcio[Squadra],$A12)=0,"",SUMIFS(Fantacalcio[VdM (mln €)],Fantacalcio[Giornata],C$4,Fantacalcio[Squadra],$A12,Fantacalcio[VotoUtile],"SI"))) -> 233.5 | D12: =IF($A12="","",IF(COUNTIFS(Fantacalcio[Giornata],D$4,Fantacalcio[Squadra],$A12)=0,"",SUMIFS(Fantacalcio[VdM (mln €)],Fantacalcio[Giornata],D$4,Fantacalcio[Squadra],$A12,Fantacalcio[VotoUtile],"SI"))) -> 182 | E12: =IF($A12="","",IF(COUNTIFS(Fantacalcio[Giornata],E$4,Fantacalcio[Squadra],$A12)=0,"",SUMIFS(Fantacalcio[VdM (mln €)],Fantacalcio[Giornata],E$4,Fantacalcio[Squadra],$A12,Fantacalcio[VotoUtile],"SI"))) -> 160 | F12: =IF($A12="","",IF(COUNTIFS(Fantacalcio[Giornata],F$4,Fantacalcio[Squadra],$A12)=0,"",SUMIFS(Fantacalcio[VdM (mln €)],Fantacalcio[Giornata],F$4,Fantacalcio[Squadra],$A12,Fantacalcio[VotoUtile],"SI"))) -> 194.5 | G12: =IF($A12="","",IF(COUNTIFS(Fantacalcio[Giornata],G$4,Fantacalcio[Squadra],$A12)=0,"",SUMIFS(Fantacalcio[VdM (mln €)],Fantacalcio[Giornata],G$4,Fantacalcio[Squadra],$A12,Fantacalcio[VotoUtile],"SI"))) -> 159.5 | H12: =IF($A12="","",IF(COUNTIFS(Fantacalcio[Giornata],H$4,Fantacalcio[Squadra],$A12)=0,"",SUMIFS(Fantacalcio[VdM (mln €)],Fantacalcio[Giornata],H$4,Fantacalcio[Squadra],$A12,Fantacalcio[VotoUtile],"SI"))) -> 211.5 | I12: =IF($A12="","",IF(COUNTIFS(Fantacalcio[Giornata],I$4,Fantacalcio[Squadra],$A12)=0,"",SUMIFS(Fantacalcio[VdM (mln €)],Fantacalcio[Giornata],I$4,Fantacalcio[Squadra],$A12,Fantacalcio[VotoUtile],"SI"))) | J12: =IF($A12="","",IF(COUNTIFS(Fantacalcio[Giornata],J$4,Fantacalcio[Squadra],$A12)=0,"",SUMIFS(Fantacalcio[VdM (mln €)],Fantacalcio[Giornata],J$4,Fantacalcio[Squadra],$A12,Fantacalcio[VotoUtile],"SI"))) | ... AN12: =IF($A12="","",IF(COUNTIFS(Fantacalcio[Giornata],AN$4,Fantacalcio[Squadra],$A12)=0,"",SUMIFS(Fantacalcio[VdM (mln €)],Fantacalcio[Giornata],AN$4,Fantacalcio[Squadra],$A12,Fantacalcio[VotoUtile],"SI")))
A13: Schalke 104 | B13: =IF($A13="","",IF(COUNT(C13:AN13)=0,"",AVERAGE(C13:AN13))) -> 210.16667 | C13: =IF($A13="","",IF(COUNTIFS(Fantacalcio[Giornata],C$4,Fantacalcio[Squadra],$A13)=0,"",SUMIFS(Fantacalcio[VdM (mln €)],Fantacalcio[Giornata],C$4,Fantacalcio[Squadra],$A13,Fantacalcio[VotoUtile],"SI"))) -> 229 | D13: =IF($A13="","",IF(COUNTIFS(Fantacalcio[Giornata],D$4,Fantacalcio[Squadra],$A13)=0,"",SUMIFS(Fantacalcio[VdM (mln €)],Fantacalcio[Giornata],D$4,Fantacalcio[Squadra],$A13,Fantacalcio[VotoUtile],"SI"))) -> 217 | E13: =IF($A13="","",IF(COUNTIFS(Fantacalcio[Giornata],E$4,Fantacalcio[Squadra],$A13)=0,"",SUMIFS(Fantacalcio[VdM (mln €)],Fantacalcio[Giornata],E$4,Fantacalcio[Squadra],$A13,Fantacalcio[VotoUtile],"SI"))) -> 205.5 | F13: =IF($A13="","",IF(COUNTIFS(Fantacalcio[Giornata],F$4,Fantacalcio[Squadra],$A13)=0,"",SUMIFS(Fantacalcio[VdM (mln €)],Fantacalcio[Giornata],F$4,Fantacalcio[Squadra],$A13,Fantacalcio[VotoUtile],"SI"))) -> 171 | G13: =IF($A13="","",IF(COUNTIFS(Fantacalcio[Giornata],G$4,Fantacalcio[Squadra],$A13)=0,"",SUMIFS(Fantacalcio[VdM (mln €)],Fantacalcio[Giornata],G$4,Fantacalcio[Squadra],$A13,Fantacalcio[VotoUtile],"SI"))) -> 217 | H13: =IF($A13="","",IF(COUNTIFS(Fantacalcio[Giornata],H$4,Fantacalcio[Squadra],$A13)=0,"",SUMIFS(Fantacalcio[VdM (mln €)],Fantacalcio[Giornata],H$4,Fantacalcio[Squadra],$A13,Fantacalcio[VotoUtile],"SI"))) -> 221.5 | I13: =IF($A13="","",IF(COUNTIFS(Fantacalcio[Giornata],I$4,Fantacalcio[Squadra],$A13)=0,"",SUMIFS(Fantacalcio[VdM (mln €)],Fantacalcio[Giornata],I$4,Fantacalcio[Squadra],$A13,Fantacalcio[VotoUtile],"SI"))) | J13: =IF($A13="","",IF(COUNTIFS(Fantacalcio[Giornata],J$4,Fantacalcio[Squadra],$A13)=0,"",SUMIFS(Fantacalcio[VdM (mln €)],Fantacalcio[Giornata],J$4,Fantacalcio[Squadra],$A13,Fantacalcio[VotoUtile],"SI"))) | ... AN13: =IF($A13="","",IF(COUNTIFS(Fantacalcio[Giornata],AN$4,Fantacalcio[Squadra],$A13)=0,"",SUMIFS(Fantacalcio[VdM (mln €)],Fantacalcio[Giornata],AN$4,Fantacalcio[Squadra],$A13,Fantacalcio[VotoUtile],"SI")))
A14: SuperGregariana | B14: =IF($A14="","",IF(COUNT(C14:AN14)=0,"",AVERAGE(C14:AN14))) -> 235.33333 | C14: =IF($A14="","",IF(COUNTIFS(Fantacalcio[Giornata],C$4,Fantacalcio[Squadra],$A14)=0,"",SUMIFS(Fantacalcio[VdM (mln €)],Fantacalcio[Giornata],C$4,Fantacalcio[Squadra],$A14,Fantacalcio[VotoUtile],"SI"))) -> 238.5 | D14: =IF($A14="","",IF(COUNTIFS(Fantacalcio[Giornata],D$4,Fantacalcio[Squadra],$A14)=0,"",SUMIFS(Fantacalcio[VdM (mln €)],Fantacalcio[Giornata],D$4,Fantacalcio[Squadra],$A14,Fantacalcio[VotoUtile],"SI"))) -> 277 | E14: =IF($A14="","",IF(COUNTIFS(Fantacalcio[Giornata],E$4,Fantacalcio[Squadra],$A14)=0,"",SUMIFS(Fantacalcio[VdM (mln €)],Fantacalcio[Giornata],E$4,Fantacalcio[Squadra],$A14,Fantacalcio[VotoUtile],"SI"))) -> 227.5 | F14: =IF($A14="","",IF(COUNTIFS(Fantacalcio[Giornata],F$4,Fantacalcio[Squadra],$A14)=0,"",SUMIFS(Fantacalcio[VdM (mln €)],Fantacalcio[Giornata],F$4,Fantacalcio[Squadra],$A14,Fantacalcio[VotoUtile],"SI"))) -> 217 | G14: =IF($A14="","",IF(COUNTIFS(Fantacalcio[Giornata],G$4,Fantacalcio[Squadra],$A14)=0,"",SUMIFS(Fantacalcio[VdM (mln €)],Fantacalcio[Giornata],G$4,Fantacalcio[Squadra],$A14,Fantacalcio[VotoUtile],"SI"))) -> 217.5 | H14: =IF($A14="","",IF(COUNTIFS(Fantacalcio[Giornata],H$4,Fantacalcio[Squadra],$A14)=0,"",SUMIFS(Fantacalcio[VdM (mln €)],Fantacalcio[Giornata],H$4,Fantacalcio[Squadra],$A14,Fantacalcio[VotoUtile],"SI"))) -> 234.5 | I14: =IF($A14="","",IF(COUNTIFS(Fantacalcio[Giornata],I$4,Fantacalcio[Squadra],$A14)=0,"",SUMIFS(Fantacalcio[VdM (mln €)],Fantacalcio[Giornata],I$4,Fantacalcio[Squadra],$A14,Fantacalcio[VotoUtile],"SI"))) | J14: =IF($A14="","",IF(COUNTIFS(Fantacalcio[Giornata],J$4,Fantacalcio[Squadra],$A14)=0,"",SUMIFS(Fantacalcio[VdM (mln €)],Fantacalcio[Giornata],J$4,Fantacalcio[Squadra],$A14,Fantacalcio[VotoUtile],"SI"))) | ... AN14: =IF($A14="","",IF(COUNTIFS(Fantacalcio[Giornata],AN$4,Fantacalcio[Squadra],$A14)=0,"",SUMIFS(Fantacalcio[VdM (mln €)],Fantacalcio[Giornata],AN$4,Fantacalcio[Squadra],$A14,Fantacalcio[VotoUtile],"SI")))
A16: Legenda
A17: Ogni cella Giornata × Squadra = somma dei VdM (mln €) dei giocatori schierati con VotoUtile = SI
A18: Media = media dei soli totali di giornata già presenti nel foglio Database
A19: Le giornate non ancora inserite nel Database restano vuote e non entrano nel calcolo della media
A20: Le squadre e i valori si aggiornano automaticamente quando vengono aggiunte nuove giornate al Database
A21: Valori espressi in milioni di euro (mln €)
A25: Classifica per VdM Medio (tutte le giornate compilate)
A26: Squadra | B26: Media VdM
A27: {=IF(ROWS($A$27:A27)>SUMPRODUCT(--ISNUMBER($B$5:$B$14)),"",INDEX(_xlfn._xlws.SORT(_xlfn._xlws.FILTER($A$5:$B$14,ISNUMBER($B$5:$B$14)),2,-1),ROWS($A$27:A27),1))} -> Mancinix | B27: {=IF(ROWS($A$27:A27)>SUMPRODUCT(--ISNUMBER($B$5:$B$14)),"",INDEX(_xlfn._xlws.SORT(_xlfn._xlws.FILTER($A$5:$B$14,ISNUMBER($B$5:$B$14)),2,-1),ROWS($A$27:A27),2))} -> 306.08333
A28: {=IF(ROWS($A$27:A28)>SUMPRODUCT(--ISNUMBER($B$5:$B$14)),"",INDEX(_xlfn._xlws.SORT(_xlfn._xlws.FILTER($A$5:$B$14,ISNUMBER($B$5:$B$14)),2,-1),ROWS($A$27:A28),1))} -> GC21 | B28: {=IF(ROWS($A$27:A28)>SUMPRODUCT(--ISNUMBER($B$5:$B$14)),"",INDEX(_xlfn._xlws.SORT(_xlfn._xlws.FILTER($A$5:$B$14,ISNUMBER($B$5:$B$14)),2,-1),ROWS($A$27:A28),2))} -> 300.83333
A29: {=IF(ROWS($A$27:A29)>SUMPRODUCT(--ISNUMBER($B$5:$B$14)),"",INDEX(_xlfn._xlws.SORT(_xlfn._xlws.FILTER($A$5:$B$14,ISNUMBER($B$5:$B$14)),2,-1),ROWS($A$27:A29),1))} -> Outletico Palermo | B29: {=IF(ROWS($A$27:A29)>SUMPRODUCT(--ISNUMBER($B$5:$B$14)),"",INDEX(_xlfn._xlws.SORT(_xlfn._xlws.FILTER($A$5:$B$14,ISNUMBER($B$5:$B$14)),2,-1),ROWS($A$27:A29),2))} -> 266.88333
A30: {=IF(ROWS($A$27:A30)>SUMPRODUCT(--ISNUMBER($B$5:$B$14)),"",INDEX(_xlfn._xlws.SORT(_xlfn._xlws.FILTER($A$5:$B$14,ISNUMBER($B$5:$B$14)),2,-1),ROWS($A$27:A30),1))} -> Incontro al capitano | B30: {=IF(ROWS($A$27:A30)>SUMPRODUCT(--ISNUMBER($B$5:$B$14)),"",INDEX(_xlfn._xlws.SORT(_xlfn._xlws.FILTER($A$5:$B$14,ISNUMBER($B$5:$B$14)),2,-1),ROWS($A$27:A30),2))} -> 251.83333
A31: {=IF(ROWS($A$27:A31)>SUMPRODUCT(--ISNUMBER($B$5:$B$14)),"",INDEX(_xlfn._xlws.SORT(_xlfn._xlws.FILTER($A$5:$B$14,ISNUMBER($B$5:$B$14)),2,-1),ROWS($A$27:A31),1))} -> SuperGregariana | B31: {=IF(ROWS($A$27:A31)>SUMPRODUCT(--ISNUMBER($B$5:$B$14)),"",INDEX(_xlfn._xlws.SORT(_xlfn._xlws.FILTER($A$5:$B$14,ISNUMBER($B$5:$B$14)),2,-1),ROWS($A$27:A31),2))} -> 235.33333
